<?xml version="1.0"?>
<!--
  Demo world consisting of a vehicle with an integrated camera and several models.
-->

<sdf version="1.6">
  <world name="integrated_camera_world">
    <physics name="1ms" type="ignored">
      <max_step_size>0.001</max_step_size>
      <real_time_factor>1.0</real_time_factor>
    </physics>
    <plugin
      filename="ignition-gazebo-physics-system"
      name="ignition::gazebo::systems::Physics">
    </plugin>
    <plugin
      filename="ignition-gazebo-sensors-system"
      name="ignition::gazebo::systems::Sensors">
      <render_engine>ogre2</render_engine>
    </plugin>
    <plugin
      filename="ignition-gazebo-scene-broadcaster-system"
      name="ignition::gazebo::systems::SceneBroadcaster">
    </plugin>
    <plugin
      filename="ignition-gazebo-user-commands-system"
      name="ignition::gazebo::systems::UserCommands">
    </plugin>

    <gui fullscreen="0">

      <!-- 3D scene -->
      <plugin filename="GzScene3D" name="3D View">
        <ignition-gui>
          <title>3D View</title>
          <property type="bool" key="showTitleBar">false</property>
          <property type="string" key="state">docked</property>
        </ignition-gui>

        <engine>ogre2</engine>
        <scene>scene</scene>
        <ambient_light>0.4 0.4 0.4</ambient_light>
        <background_color>0.8 0.8 0.8</background_color>
        <camera_pose>-6 0 6 0 0.5 0</camera_pose>
      </plugin>

      <!-- World control -->
      <plugin filename="WorldControl" name="World control">
        <ignition-gui>
          <title>World control</title>
          <property type="bool" key="showTitleBar">false</property>
          <property type="bool" key="resizable">false</property>
          <property type="double" key="height">72</property>
          <property type="double" key="width">121</property>
          <property type="double" key="z">1</property>

          <property type="string" key="state">floating</property>
          <anchors target="3D View">
            <line own="left" target="left"/>
            <line own="bottom" target="bottom"/>
          </anchors>
        </ignition-gui>

        <play_pause>true</play_pause>
        <step>true</step>
        <start_paused>true</start_paused>
        <service>/world/integrated_camera_world/control</service>
        <stats_topic>/world/integrated_camera_world/stats</stats_topic>

      </plugin>

      <!-- World statistics -->
      <plugin filename="WorldStats" name="World stats">
        <ignition-gui>
          <title>World stats</title>
          <property type="bool" key="showTitleBar">false</property>
          <property type="bool" key="resizable">false</property>
          <property type="double" key="height">110</property>
          <property type="double" key="width">290</property>
          <property type="double" key="z">1</property>

          <property type="string" key="state">floating</property>
          <anchors target="3D View">
            <line own="right" target="right"/>
            <line own="bottom" target="bottom"/>
          </anchors>
        </ignition-gui>

        <sim_time>true</sim_time>
        <real_time>true</real_time>
        <real_time_factor>true</real_time_factor>
        <iterations>true</iterations>
        <topic>/world/integrated_camera_world/stats</topic>
      </plugin>

      <!-- Camera Display Plugin -->
      <plugin filename="ImageDisplay" name="Image Display">
        <ignition-gui>
          <title>Integrated Camera</title>
          <property key="state" type="string">floating</property>
          <property type="double" key="width">350</property>
          <property type="double" key="height">315</property>
        </ignition-gui>
        <topic>vehicle_blue/camera</topic>
        <topic_picker>false</topic_picker>
      </plugin>

    </gui>

    <light type="directional" name="sun">
      <cast_shadows>true</cast_shadows>
      <pose>0 0 10 0 0 0</pose>
      <diffuse>0.8 0.8 0.8 1</diffuse>
      <specular>0.2 0.2 0.2 1</specular>
      <attenuation>
        <range>1000</range>
        <constant>0.9</constant>
        <linear>0.01</linear>
        <quadratic>0.001</quadratic>
      </attenuation>
      <direction>-0.5 0.1 -0.9</direction>
    </light>
    
    <atmosphere type="adiabatic">
      <temperature>300</temperature>
    </atmosphere>

    <!-- Vehicle Blue Model with Integrated Camera -->
    <model name="vehicle_blue">
      <pose relative_to='world'>0 0 0 0 0 0</pose>

      <!--chassis-->
      <link name='chassis'>
          <pose relative_to='__model__'>0.5 0 0.4 0 0 0</pose>
          <inertial>
              <mass>1.14395</mass>
              <inertia>
                  <ixx>0.095329</ixx>
                  <ixy>0</ixy>
                  <ixz>0</ixz>
                  <iyy>0.381317</iyy>
                  <iyz>0</iyz>
                  <izz>0.476646</izz>
              </inertia>
          </inertial>
          <visual name='visual'>
              <geometry>
                  <box>
                      <size>2.0 1.0 0.5</size>
                  </box>
              </geometry>
              <material>
                  <ambient>0.0 0.0 1.0 1</ambient>
                  <diffuse>0.0 0.0 1.0 1</diffuse>
                  <specular>0.0 0.0 1.0 1</specular>
              </material>
          </visual>
          <collision name='collision'>
              <geometry>
                  <box>
                      <size>2.0 1.0 0.5</size>
                  </box>
              </geometry>
          </collision>
          <sensor name="imu_sensor" type="imu">
              <always_on>1</always_on>
              <update_rate>1</update_rate>
              <visualize>true</visualize>
              <topic>imu</topic>
          </sensor>
      </link>

      <!--Left wheel-->
      <link name='left_wheel'>
          <pose relative_to="chassis">-0.5 0.6 0 -1.5707 0 0</pose>
          <inertial>
              <mass>1</mass>
              <inertia>
                  <ixx>0.043333</ixx>
                  <ixy>0</ixy>
                  <ixz>0</ixz>
                  <iyy>0.043333</iyy>
                  <iyz>0</iyz>
                  <izz>0.08</izz>
              </inertia>
          </inertial>
          <visual name='visual'>
              <geometry>
                  <cylinder>
                      <radius>0.4</radius>
                      <length>0.2</length>
                  </cylinder>
              </geometry>
              <material>
                  <ambient>1.0 0.0 0.0 1</ambient>
                  <diffuse>1.0 0.0 0.0 1</diffuse>
                  <specular>1.0 0.0 0.0 1</specular>
              </material>
          </visual>
          <collision name='collision'>
              <geometry>
                  <cylinder>
                      <radius>0.4</radius>
                      <length>0.2</length>
                  </cylinder>
              </geometry>
          </collision>
      </link>

      <!--The same as left wheel but with different position-->
      <link name='right_wheel'>
          <pose relative_to="chassis">-0.5 -0.6 0 -1.5707 0 0</pose>
          <inertial>
              <mass>1</mass>
              <inertia>
                  <ixx>0.043333</ixx>
                  <ixy>0</ixy>
                  <ixz>0</ixz>
                  <iyy>0.043333</iyy>
                  <iyz>0</iyz>
                  <izz>0.08</izz>
              </inertia>
          </inertial>
          <visual name='visual'>
              <geometry>
                  <cylinder>
                      <radius>0.4</radius>
                      <length>0.2</length>
                  </cylinder>
              </geometry>
              <material>
                  <ambient>1.0 0.0 0.0 1</ambient>
                  <diffuse>1.0 0.0 0.0 1</diffuse>
                  <specular>1.0 0.0 0.0 1</specular>
              </material>
          </visual>
          <collision name='collision'>
              <geometry>
                  <cylinder>
                      <radius>0.4</radius>
                      <length>0.2</length>
                  </cylinder>
              </geometry>
          </collision>
      </link>

      <!--arbitrary frame-->
      <frame name="caster_frame" attached_to='chassis'>
          <pose>0.8 0 -0.2 0 0 0</pose>
      </frame>

      <!--caster wheel-->
      <link name='caster'>
          <pose relative_to='caster_frame'/>
          <inertial>
              <mass>1</mass>
              <inertia>
                  <ixx>0.016</ixx>
                  <ixy>0</ixy>
                  <ixz>0</ixz>
                  <iyy>0.016</iyy>
                  <iyz>0</iyz>
                  <izz>0.016</izz>
              </inertia>
          </inertial>
          <visual name='visual'>
              <geometry>
                  <sphere>
                      <radius>0.2</radius>
                  </sphere>
              </geometry>
              <material>
                  <ambient>0.0 1.0 0.0 1</ambient>
                  <diffuse>0.0 1.0 0.0 1</diffuse>
                  <specular>0.0 1.0 0.0 1</specular>
              </material>
          </visual>
          <collision name='collision'>
              <geometry>
                  <sphere>
                      <radius>0.2</radius>
                  </sphere>
              </geometry>
          </collision>
      </link>

      <!--left wheel joint-->
      <joint name='left_wheel_joint' type='revolute'>
          <pose relative_to='left_wheel'/>
          <parent>chassis</parent>
          <child>left_wheel</child>
          <axis>
              <xyz expressed_in='__model__'>0 1 0</xyz>
              <limit>
                  <lower>-1.79769e+308</lower>    <!--negative infinity-->
                  <upper>1.79769e+308</upper>     <!--positive infinity-->
              </limit>
          </axis>
      </joint>

      <!--right wheel joint-->
      <joint name='right_wheel_joint' type='revolute'>
          <pose relative_to='right_wheel'/>
          <parent>chassis</parent>
          <child>right_wheel</child>
          <axis>
              <xyz expressed_in='__model__'>0 1 0</xyz>
              <limit>
                  <lower>-1.79769e+308</lower>    <!--negative infinity-->
                  <upper>1.79769e+308</upper>     <!--positive infinity-->
              </limit>
          </axis>
      </joint>

      <!--caster wheel joint-->
      <joint name='caster_wheel' type='ball'>
          <parent>chassis</parent>
          <child>caster</child>
      </joint>

      <plugin
          filename="gz-sim-diff-drive-system"
          name="gz::sim::systems::DiffDrive">
          <left_joint>left_wheel_joint</left_joint>
          <right_joint>right_wheel_joint</right_joint>
          <wheel_separation>1.2</wheel_separation>
          <wheel_radius>0.4</wheel_radius>
          <odom_publish_frequency>1</odom_publish_frequency>
          <topic>cmd_vel</topic>
      </plugin>

      <!-- Camera Sensor -->
      <link name="camera_link">
        <pose>0.1 0 0.2 0 0 0</pose>
        <sensor name="vehicle_blue_camera" type="camera">
          <camera>
            <horizontal_fov>1.047</horizontal_fov>
            <image>
              <width>640</width>
              <height>480</height>
              <format>R8G8B8</format>
            </image>
            <clip>
              <near>0.1</near>
              <far>100</far>
            </clip>
          </camera>
          <always_on>1</always_on>
          <update_rate>30</update_rate>
          <visualize>true</visualize>
          <topic>vehicle_blue/camera</topic>
        </sensor>
      </link>

      <static>true</static>
    </model>

    <!-- Example included models -->
    <include>
      <pose>1 0 0 0 0 1.570796</pose>
      <name>rescue_randy</name>
      <uri>https://fuel.ignitionrobotics.org/1.0/OpenRobotics/models/Rescue Randy</uri>
    </include>

    <include>
      <pose>2.25 .5 .1 0 0 1.570796</pose>
      <name>phone</name>
      <uri>https://fuel.ignitionrobotics.org/1.0/OpenRobotics/models/Samsung J8 Black</uri>
    </include>

    <include>
      <pose>2.25 -.5 .1 0 0 1.570796</pose>
      <name>backpack</name>
      <uri>https://fuel.ignitionrobotics.org/1.0/OpenRobotics/models/Backpack</uri>
    </include>

  </world>
</sdf>
